[
    {
        "url": "https://api.github.com/repos/abhishekmalle/FaceCheck/issues/2",
        "repository_url": "https://api.github.com/repos/abhishekmalle/FaceCheck",
        "labels_url": "https://api.github.com/repos/abhishekmalle/FaceCheck/issues/2/labels{/name}",
        "comments_url": "https://api.github.com/repos/abhishekmalle/FaceCheck/issues/2/comments",
        "events_url": "https://api.github.com/repos/abhishekmalle/FaceCheck/issues/2/events",
        "html_url": "https://github.com/abhishekmalle/FaceCheck/issues/2",
        "id": 382795111,
        "node_id": "MDU6SXNzdWUzODI3OTUxMTE=",
        "number": 2,
        "title": "Detecting unknown people as known dataset",
        "user": {
            "login": "SijinJohn",
            "id": 45029183,
            "node_id": "MDQ6VXNlcjQ1MDI5MTgz",
            "avatar_url": "https://avatars1.githubusercontent.com/u/45029183?v=4",
            "gravatar_id": "",
            "url": "https://api.github.com/users/SijinJohn",
            "html_url": "https://github.com/SijinJohn",
            "followers_url": "https://api.github.com/users/SijinJohn/followers",
            "following_url": "https://api.github.com/users/SijinJohn/following{/other_user}",
            "gists_url": "https://api.github.com/users/SijinJohn/gists{/gist_id}",
            "starred_url": "https://api.github.com/users/SijinJohn/starred{/owner}{/repo}",
            "subscriptions_url": "https://api.github.com/users/SijinJohn/subscriptions",
            "organizations_url": "https://api.github.com/users/SijinJohn/orgs",
            "repos_url": "https://api.github.com/users/SijinJohn/repos",
            "events_url": "https://api.github.com/users/SijinJohn/events{/privacy}",
            "received_events_url": "https://api.github.com/users/SijinJohn/received_events",
            "type": "User",
            "site_admin": false
        },
        "labels": [],
        "state": "open",
        "locked": false,
        "assignee": null,
        "assignees": [],
        "milestone": null,
        "comments": 0,
        "created_at": "2018-11-20T18:31:31Z",
        "updated_at": "2018-11-20T18:31:31Z",
        "closed_at": null,
        "author_association": "NONE",
        "body": "I like your model ,but the issue when is run  face_detection_sample.py, in most cases it detects unknown people as known dataset. Is there any solution for it??"
    },
    {
        "url": "https://api.github.com/repos/abhishekmalle/FaceCheck/issues/1",
        "repository_url": "https://api.github.com/repos/abhishekmalle/FaceCheck",
        "labels_url": "https://api.github.com/repos/abhishekmalle/FaceCheck/issues/1/labels{/name}",
        "comments_url": "https://api.github.com/repos/abhishekmalle/FaceCheck/issues/1/comments",
        "events_url": "https://api.github.com/repos/abhishekmalle/FaceCheck/issues/1/events",
        "html_url": "https://github.com/abhishekmalle/FaceCheck/issues/1",
        "id": 381734347,
        "node_id": "MDU6SXNzdWUzODE3MzQzNDc=",
        "number": 1,
        "title": "error while installing face_recognition",
        "user": {
            "login": "SijinJohn",
            "id": 45029183,
            "node_id": "MDQ6VXNlcjQ1MDI5MTgz",
            "avatar_url": "https://avatars1.githubusercontent.com/u/45029183?v=4",
            "gravatar_id": "",
            "url": "https://api.github.com/users/SijinJohn",
            "html_url": "https://github.com/SijinJohn",
            "followers_url": "https://api.github.com/users/SijinJohn/followers",
            "following_url": "https://api.github.com/users/SijinJohn/following{/other_user}",
            "gists_url": "https://api.github.com/users/SijinJohn/gists{/gist_id}",
            "starred_url": "https://api.github.com/users/SijinJohn/starred{/owner}{/repo}",
            "subscriptions_url": "https://api.github.com/users/SijinJohn/subscriptions",
            "organizations_url": "https://api.github.com/users/SijinJohn/orgs",
            "repos_url": "https://api.github.com/users/SijinJohn/repos",
            "events_url": "https://api.github.com/users/SijinJohn/events{/privacy}",
            "received_events_url": "https://api.github.com/users/SijinJohn/received_events",
            "type": "User",
            "site_admin": false
        },
        "labels": [],
        "state": "open",
        "locked": false,
        "assignee": null,
        "assignees": [],
        "milestone": null,
        "comments": 7,
        "created_at": "2018-11-16T19:41:43Z",
        "updated_at": "2019-04-26T00:27:11Z",
        "closed_at": null,
        "author_association": "NONE",
        "body": "Hi i am getting error while instaling face_recognition.\r\nTraceback (most recent call last):\r\n    File \"C:\\Users\\SIJIN~1.JOH\\AppData\\Local\\Temp\\pip-install-ou6izibi\\dlib\\setup.py\", line 118, in get_cmake_version\r\n      out = subprocess.check_output(['cmake', '--version'])\r\n    File \"c:\\users\\sijin.john\\appdata\\local\\programs\\python\\python36\\lib\\subprocess.py\", line 336, in check_output\r\n      **kwargs).stdout\r\n    File \"c:\\users\\sijin.john\\appdata\\local\\programs\\python\\python36\\lib\\subprocess.py\", line 403, in run\r\n      with Popen(*popenargs, **kwargs) as process:\r\n    File \"c:\\users\\sijin.john\\appdata\\local\\programs\\python\\python36\\lib\\subprocess.py\", line 709, in __init__\r\n      restore_signals, start_new_session)\r\n    File \"c:\\users\\sijin.john\\appdata\\local\\programs\\python\\python36\\lib\\subprocess.py\", line 997, in _execute_child\r\n      startupinfo)\r\n  FileNotFoundError: [WinError 2] The system cannot find the file specified\r\n\r\n  During handling of the above exception, another exception occurred:\r\n\r\n  Traceback (most recent call last):\r\n    File \"<string>\", line 1, in <module>\r\n    File \"C:\\Users\\SIJIN~1.JOH\\AppData\\Local\\Temp\\pip-install-ou6izibi\\dlib\\setup.py\", line 257, in <module>\r\n      'Topic :: Software Development',\r\n    File \"c:\\users\\sijin.john\\appdata\\local\\programs\\python\\python36\\lib\\site-packages\\setuptools\\__init__.py\", line 129, in setup\r\n      return distutils.core.setup(**attrs)\r\n    File \"c:\\users\\sijin.john\\appdata\\local\\programs\\python\\python36\\lib\\distutils\\core.py\", line 148, in setup\r\n      dist.run_commands()\r\n    File \"c:\\users\\sijin.john\\appdata\\local\\programs\\python\\python36\\lib\\distutils\\dist.py\", line 955, in run_commands\r\n      self.run_command(cmd)\r\n    File \"c:\\users\\sijin.john\\appdata\\local\\programs\\python\\python36\\lib\\distutils\\dist.py\", line 974, in run_command\r\n      cmd_obj.run()\r\n    File \"c:\\users\\sijin.john\\appdata\\local\\programs\\python\\python36\\lib\\site-packages\\wheel\\bdist_wheel.py\", line 188, in run\r\n      self.run_command('build')\r\n    File \"c:\\users\\sijin.john\\appdata\\local\\programs\\python\\python36\\lib\\distutils\\cmd.py\", line 313, in run_command\r\n      self.distribution.run_command(command)\r\n    File \"c:\\users\\sijin.john\\appdata\\local\\programs\\python\\python36\\lib\\distutils\\dist.py\", line 974, in run_command\r\n      cmd_obj.run()\r\n    File \"c:\\users\\sijin.john\\appdata\\local\\programs\\python\\python36\\lib\\distutils\\command\\build.py\", line 135, in run\r\n      self.run_command(cmd_name)\r\n    File \"c:\\users\\sijin.john\\appdata\\local\\programs\\python\\python36\\lib\\distutils\\cmd.py\", line 313, in run_command\r\n      self.distribution.run_command(command)\r\n    File \"c:\\users\\sijin.john\\appdata\\local\\programs\\python\\python36\\lib\\distutils\\dist.py\", line 974, in run_command\r\n      cmd_obj.run()\r\n    File \"C:\\Users\\SIJIN~1.JOH\\AppData\\Local\\Temp\\pip-install-ou6izibi\\dlib\\setup.py\", line 127, in run\r\n      cmake_version = self.get_cmake_version()\r\n    File \"C:\\Users\\SIJIN~1.JOH\\AppData\\Local\\Temp\\pip-install-ou6izibi\\dlib\\setup.py\", line 123, in get_cmake_version\r\n      \"\\n*******************************************************************\\n\")\r\n  RuntimeError:\r\n  *******************************************************************\r\n   CMake must be installed to build the following extensions: dlib\r\n  *******************************************************************\r\n\r\n\r\n  ----------------------------------------\r\n  Failed building wheel for dlib\r\n  Running setup.py clean for dlib\r\n  Running setup.py bdist_wheel for face-recognition-models ... done\r\n  Stored in directory: C:\\Users\\sijin.john\\AppData\\Local\\pip\\Cache\\wheels\\d2\\99\\18\\59c6c8f01e39810415c0e63f5bede7d83dfb0ffc039865465f\r\nSuccessfully built face-recognition-models\r\nFailed to build dlib\r\nInstalling collected packages: Click, dlib, face-recognition-models, face-recognition\r\n  Running setup.py install for dlib ... error\r\n    Complete output from command c:\\users\\sijin.john\\appdata\\local\\programs\\python\\python36\\python.exe -u -c \"import setuptools, tokenize;__file__='C:\\\\Users\\\\SIJIN~1.JOH\\\\AppData\\\\Local\\\\Temp\\\\pip-install-ou6izibi\\\\dlib\\\\setup.py';f=getattr(tokenize, 'open', open)(__file__);code=f.read().replace('\\r\\n', '\\n');f.close();exec(compile(code, __file__, 'exec'))\" install --record C:\\Users\\SIJIN~1.JOH\\AppData\\Local\\Temp\\pip-record-iep41c2h\\install-record.txt --single-version-externally-managed --compile:\r\n    running install\r\n    running build\r\n    running build_py\r\n    package init file 'dlib\\__init__.py' not found (or not a regular file)\r\n    running build_ext\r\n    Traceback (most recent call last):\r\n      File \"C:\\Users\\SIJIN~1.JOH\\AppData\\Local\\Temp\\pip-install-ou6izibi\\dlib\\setup.py\", line 118, in get_cmake_version\r\n        out = subprocess.check_output(['cmake', '--version'])\r\n      File \"c:\\users\\sijin.john\\appdata\\local\\programs\\python\\python36\\lib\\subprocess.py\", line 336, in check_output\r\n        **kwargs).stdout\r\n      File \"c:\\users\\sijin.john\\appdata\\local\\programs\\python\\python36\\lib\\subprocess.py\", line 403, in run\r\n        with Popen(*popenargs, **kwargs) as process:\r\n      File \"c:\\users\\sijin.john\\appdata\\local\\programs\\python\\python36\\lib\\subprocess.py\", line 709, in __init__\r\n        restore_signals, start_new_session)\r\n      File \"c:\\users\\sijin.john\\appdata\\local\\programs\\python\\python36\\lib\\subprocess.py\", line 997, in _execute_child\r\n        startupinfo)\r\n    FileNotFoundError: [WinError 2] The system cannot find the file specified\r\n\r\n    During handling of the above exception, another exception occurred:\r\n\r\n    Traceback (most recent call last):\r\n      File \"<string>\", line 1, in <module>\r\n      File \"C:\\Users\\SIJIN~1.JOH\\AppData\\Local\\Temp\\pip-install-ou6izibi\\dlib\\setup.py\", line 257, in <module>\r\n        'Topic :: Software Development',\r\n      File \"c:\\users\\sijin.john\\appdata\\local\\programs\\python\\python36\\lib\\site-packages\\setuptools\\__init__.py\", line 129, in setup\r\n        return distutils.core.setup(**attrs)\r\n      File \"c:\\users\\sijin.john\\appdata\\local\\programs\\python\\python36\\lib\\distutils\\core.py\", line 148, in setup\r\n        dist.run_commands()\r\n      File \"c:\\users\\sijin.john\\appdata\\local\\programs\\python\\python36\\lib\\distutils\\dist.py\", line 955, in run_commands\r\n        self.run_command(cmd)\r\n      File \"c:\\users\\sijin.john\\appdata\\local\\programs\\python\\python36\\lib\\distutils\\dist.py\", line 974, in run_command\r\n        cmd_obj.run()\r\n      File \"c:\\users\\sijin.john\\appdata\\local\\programs\\python\\python36\\lib\\site-packages\\setuptools\\command\\install.py\", line 61, in run\r\n        return orig.install.run(self)\r\n      File \"c:\\users\\sijin.john\\appdata\\local\\programs\\python\\python36\\lib\\distutils\\command\\install.py\", line 545, in run\r\n        self.run_command('build')\r\n      File \"c:\\users\\sijin.john\\appdata\\local\\programs\\python\\python36\\lib\\distutils\\cmd.py\", line 313, in run_command\r\n        self.distribution.run_command(command)\r\n      File \"c:\\users\\sijin.john\\appdata\\local\\programs\\python\\python36\\lib\\distutils\\dist.py\", line 974, in run_command\r\n        cmd_obj.run()\r\n      File \"c:\\users\\sijin.john\\appdata\\local\\programs\\python\\python36\\lib\\distutils\\command\\build.py\", line 135, in run\r\n        self.run_command(cmd_name)\r\n      File \"c:\\users\\sijin.john\\appdata\\local\\programs\\python\\python36\\lib\\distutils\\cmd.py\", line 313, in run_command\r\n        self.distribution.run_command(command)\r\n      File \"c:\\users\\sijin.john\\appdata\\local\\programs\\python\\python36\\lib\\distutils\\dist.py\", line 974, in run_command\r\n        cmd_obj.run()\r\n      File \"C:\\Users\\SIJIN~1.JOH\\AppData\\Local\\Temp\\pip-install-ou6izibi\\dlib\\setup.py\", line 127, in run\r\n        cmake_version = self.get_cmake_version()\r\n      File \"C:\\Users\\SIJIN~1.JOH\\AppData\\Local\\Temp\\pip-install-ou6izibi\\dlib\\setup.py\", line 123, in get_cmake_version\r\n        \"\\n*******************************************************************\\n\")\r\n    RuntimeError:\r\n    *******************************************************************\r\n     CMake must be installed to build the following extensions: dlib\r\n    *******************************************************************\r\n\r\n\r\n    ----------------------------------------\r\nCommand \"c:\\users\\sijin.john\\appdata\\local\\programs\\python\\python36\\python.exe -u -c \"import setuptools, tokenize;__file__='C:\\\\Users\\\\SIJIN~1.JOH\\\\AppData\\\\Local\\\\Temp\\\\pip-install-ou6izibi\\\\dlib\\\\setup.py';f=getattr(tokenize, 'open', open)(__file__);code=f.read().replace('\\r\\n', '\\n');f.close();exec(compile(code, __file__, 'exec'))\" install --record C:\\Users\\SIJIN~1.JOH\\AppData\\Local\\Temp\\pip-record-iep41c2h\\install-record.txt --single-version-externally-managed --compile\" failed with error code 1 in C:\\Users\\SIJIN~1.JOH\\AppData\\Local\\Temp\\pip-install-ou6izi"
    }
]