[
    {
        "url": "https://api.github.com/repos/ex0dus-0x/pwnduino/issues/2",
        "repository_url": "https://api.github.com/repos/ex0dus-0x/pwnduino",
        "labels_url": "https://api.github.com/repos/ex0dus-0x/pwnduino/issues/2/labels{/name}",
        "comments_url": "https://api.github.com/repos/ex0dus-0x/pwnduino/issues/2/comments",
        "events_url": "https://api.github.com/repos/ex0dus-0x/pwnduino/issues/2/events",
        "html_url": "https://github.com/ex0dus-0x/pwnduino/issues/2",
        "id": 512353376,
        "node_id": "MDU6SXNzdWU1MTIzNTMzNzY=",
        "number": 2,
        "title": "Problem with pwnduino.py",
        "user": {
            "login": "ze44lk",
            "id": 37210862,
            "node_id": "MDQ6VXNlcjM3MjEwODYy",
            "avatar_url": "https://avatars3.githubusercontent.com/u/37210862?v=4",
            "gravatar_id": "",
            "url": "https://api.github.com/users/ze44lk",
            "html_url": "https://github.com/ze44lk",
            "followers_url": "https://api.github.com/users/ze44lk/followers",
            "following_url": "https://api.github.com/users/ze44lk/following{/other_user}",
            "gists_url": "https://api.github.com/users/ze44lk/gists{/gist_id}",
            "starred_url": "https://api.github.com/users/ze44lk/starred{/owner}{/repo}",
            "subscriptions_url": "https://api.github.com/users/ze44lk/subscriptions",
            "organizations_url": "https://api.github.com/users/ze44lk/orgs",
            "repos_url": "https://api.github.com/users/ze44lk/repos",
            "events_url": "https://api.github.com/users/ze44lk/events{/privacy}",
            "received_events_url": "https://api.github.com/users/ze44lk/received_events",
            "type": "User",
            "site_admin": false
        },
        "labels": [],
        "state": "open",
        "locked": false,
        "assignee": null,
        "assignees": [],
        "milestone": null,
        "comments": 0,
        "created_at": "2019-10-25T07:34:06Z",
        "updated_at": "2019-10-25T07:34:06Z",
        "closed_at": null,
        "author_association": "NONE",
        "body": "Hi,\r\nWhen I execute the py script, I get this message:\r\n\r\n> Unable to call dfu-programmer command. Is it installed or in PATH?\r\nSo I edited the script to see if there was any kind of problem, but everything looks right, except the line that executes \r\n\r\n> dfu-programmer --help\r\nwich returns an error\r\n\r\n> status, _ = commands.getstatusoutput('dfu-programmer --help')\r\n    if status != 0:\r\n        print(\"Unable to call dfu-programmer command. Is it installed or in PATH?\")\r\n        exit(1)\r\nI tried the command on the shell, and it works. I don't actually understand the problem I got here.\r\nIf anybody has an answer to this, let me know.\r\nze4lk\r\n\r\n\r\n"
    },
    {
        "url": "https://api.github.com/repos/ex0dus-0x/pwnduino/issues/1",
        "repository_url": "https://api.github.com/repos/ex0dus-0x/pwnduino",
        "labels_url": "https://api.github.com/repos/ex0dus-0x/pwnduino/issues/1/labels{/name}",
        "comments_url": "https://api.github.com/repos/ex0dus-0x/pwnduino/issues/1/comments",
        "events_url": "https://api.github.com/repos/ex0dus-0x/pwnduino/issues/1/events",
        "html_url": "https://github.com/ex0dus-0x/pwnduino/issues/1",
        "id": 345603741,
        "node_id": "MDU6SXNzdWUzNDU2MDM3NDE=",
        "number": 1,
        "title": "Problem when dowloading/installing",
        "user": {
            "login": "jack6972",
            "id": 41884560,
            "node_id": "MDQ6VXNlcjQxODg0NTYw",
            "avatar_url": "https://avatars3.githubusercontent.com/u/41884560?v=4",
            "gravatar_id": "",
            "url": "https://api.github.com/users/jack6972",
            "html_url": "https://github.com/jack6972",
            "followers_url": "https://api.github.com/users/jack6972/followers",
            "following_url": "https://api.github.com/users/jack6972/following{/other_user}",
            "gists_url": "https://api.github.com/users/jack6972/gists{/gist_id}",
            "starred_url": "https://api.github.com/users/jack6972/starred{/owner}{/repo}",
            "subscriptions_url": "https://api.github.com/users/jack6972/subscriptions",
            "organizations_url": "https://api.github.com/users/jack6972/orgs",
            "repos_url": "https://api.github.com/users/jack6972/repos",
            "events_url": "https://api.github.com/users/jack6972/events{/privacy}",
            "received_events_url": "https://api.github.com/users/jack6972/received_events",
            "type": "User",
            "site_admin": false
        },
        "labels": [],
        "state": "open",
        "locked": false,
        "assignee": null,
        "assignees": [],
        "milestone": null,
        "comments": 1,
        "created_at": "2018-07-30T04:04:25Z",
        "updated_at": "2018-12-08T03:04:14Z",
        "closed_at": null,
        "author_association": "NONE",
        "body": "Everything works until the Dowloading and Installation section when I enter: sudo pip install signal pyserial arduino-sketch\r\nThen the following come up:\r\n\r\nDownloading/unpacking signal\r\n   Could not find any downloads that satisfy the requirement signal\r\nCleaning up...\r\nNo distributions at all found for signal\r\nStoring debug logs for failure in /root/.pip/pip.log"
    }
]